import two_functions

# TODO How is DOCSTRING_TEST answered with an exception?

print(two_functions.add_two_numbers(4, 6))
print(two_functions.add_two_numbers("torsdag"))